Workbook

Sheet Promises
A1: # | B1: Promise | C1: Reference | D1: Speaker | E1: Recipient | F1: Category | G1: Conditional / Unconditional | H1: Vol
A2: 1 | B2: The Seed of the woman will bruise the serpent's head | C2: Genesis 3:15 | D2: God | E2: Humanity (via the serpent) | F2: Redemption / Messiah | G2: Unconditional | H2: 1
A3: 2 | B3: God will put enmity between the serpent and the woman, and between their seeds | C3: Genesis 3:15 | D3: God | E3: Humanity | F3: Redemption | G3: Unconditional | H3: 1
A4: 3 | B4: Whoever kills Cain will suffer vengeance sevenfold | C4: Genesis 4:15 | D4: God | E4: Cain | F4: Protection | G4: Unconditional | H4: 1
A5: 4 | B5: God will establish His covenant with Noah | C5: Genesis 6:18 | D5: God | E5: Noah | F5: Covenant | G5: Unconditional | H5: 1
A6: 5 | B6: Noah, his family, and the animals will enter and be preserved in the ark | C6: Genesis 6:18 | D6: God | E6: Noah | F6: Deliverance | G6: Conditional | H6: 1
A7: 6 | B7: In seven days God will send rain forty days and nights and destroy every living thing He made | C7: Genesis 7:4 | D7: God | E7: Noah | F7: Judgment | G7: Unconditional | H7: 1
A8: 7 | B8: God will never again curse the ground for man's sake | C8: Genesis 8:21 | D8: God | E8: Noah / Humanity | F8: Mercy | G8: Unconditional | H8: 1
A9: 8 | B9: God will never again destroy every living thing as He had done | C9: Genesis 8:21 | D9: God | E9: Humanity | F9: Mercy | G9: Unconditional | H9: 1
A10: 9 | B10: While the earth remains, seedtime, harvest, cold, heat, summer, winter, day and night shall not cease | C10: Genesis 8:22 | D10: God | E10: Humanity | F10: Providence | G10: Unconditional | H10: 1
A11: 10 | B11: God establishes His covenant with Noah, his descendants, and every living creature | C11: Genesis 9:9-10 | D11: God | E11: Noah and all creation | F11: Covenant | G11: Unconditional | H11: 1
A12: 11 | B12: Never again shall all flesh be cut off by flood waters | C12: Genesis 9:11 | D12: God | E12: All creation | F12: Covenant | G12: Unconditional | H12: 1
A13: 12 | B13: Never again shall a flood destroy the earth | C13: Genesis 9:11 | D13: God | E13: All creation | F13: Covenant | G13: Unconditional | H13: 1
... A1047: 1046 | B1047: Surely I am coming quickly | C1047: Revelation 22:20 | D1047: Jesus | E1047: The Church | F1047: Second Coming | G1047: Unconditional | H1047: 1

Sheet Totals by Book
A1: Book | B1: Promises Indexed
A2: Genesis | B2: =COUNTIF(Promises!$C$2:$C$1047,"Genesis *") -> 76
A3: Exodus | B3: =COUNTIF(Promises!$C$2:$C$1047,"Exodus *") -> 41
A4: Leviticus | B4: =COUNTIF(Promises!$C$2:$C$1047,"Leviticus *") -> 13
A5: Numbers | B5: =COUNTIF(Promises!$C$2:$C$1047,"Numbers *") -> 16
A6: Deuteronomy | B6: =COUNTIF(Promises!$C$2:$C$1047,"Deuteronomy *") -> 64
A7: Joshua | B7: =COUNTIF(Promises!$C$2:$C$1047,"Joshua *") -> 13
A8: Judges | B8: =COUNTIF(Promises!$C$2:$C$1047,"Judges *") -> 8
A9: Ruth | B9: =COUNTIF(Promises!$C$2:$C$1047,"Ruth *") -> 1
A10: 1 Samuel | B10: =COUNTIF(Promises!$C$2:$C$1047,"1 Samuel *") -> 10
A11: 2 Samuel | B11: =COUNTIF(Promises!$C$2:$C$1047,"2 Samuel *") -> 11
A12: 1 Kings | B12: =COUNTIF(Promises!$C$2:$C$1047,"1 Kings *") -> 12
A13: 2 Kings | B13: =COUNTIF(Promises!$C$2:$C$1047,"2 Kings *") -> 6
A14: 1 Chronicles | B14: =COUNTIF(Promises!$C$2:$C$1047,"1 Chronicles *") -> 8
A15: 2 Chronicles | B15: =COUNTIF(Promises!$C$2:$C$1047,"2 Chronicles *") -> 7
A16: Ezra | B16: =COUNTIF(Promises!$C$2:$C$1047,"Ezra *") -> 1
A17: Nehemiah | B17: =COUNTIF(Promises!$C$2:$C$1047,"Nehemiah *") -> 1
A18: Job | B18: =COUNTIF(Promises!$C$2:$C$1047,"Job *") -> 3
A19: Psalms | B19: =COUNTIF(Promises!$C$2:$C$1047,"Psalm *") -> 131
A20: Proverbs | B20: =COUNTIF(Promises!$C$2:$C$1047,"Proverbs *") -> 16
A21: Ecclesiastes | B21: =COUNTIF(Promises!$C$2:$C$1047,"Ecclesiastes *") -> 2
A22: Isaiah | B22: =COUNTIF(Promises!$C$2:$C$1047,"Isaiah *") -> 150
A23: Jeremiah | B23: =COUNTIF(Promises!$C$2:$C$1047,"Jeremiah *") -> 67
A24: Lamentations | B24: =COUNTIF(Promises!$C$2:$C$1047,"Lamentations *") -> 3
A25: Ezekiel | B25: =COUNTIF(Promises!$C$2:$C$1047,"Ezekiel *") -> 45
A26: Daniel | B26: =COUNTIF(Promises!$C$2:$C$1047,"Daniel *") -> 8
A27: Hosea | B27: =COUNTIF(Promises!$C$2:$C$1047,"Hosea *") -> 7
A28: Joel | B28: =COUNTIF(Promises!$C$2:$C$1047,"Joel *") -> 6
A29: Amos | B29: =COUNTIF(Promises!$C$2:$C$1047,"Amos *") -> 3
A30: Obadiah | B30: =COUNTIF(Promises!$C$2:$C$1047,"Obadiah *") -> 3
A31: Jonah | B31: =COUNTIF(Promises!$C$2:$C$1047,"Jonah *") -> 1
A32: Micah | B32: =COUNTIF(Promises!$C$2:$C$1047,"Micah *") -> 5
A33: Nahum | B33: =COUNTIF(Promises!$C$2:$C$1047,"Nahum *") -> 1
A34: Habakkuk | B34: =COUNTIF(Promises!$C$2:$C$1047,"Habakkuk *") -> 3
A35: Zephaniah | B35: =COUNTIF(Promises!$C$2:$C$1047,"Zephaniah *") -> 5
A36: Haggai | B36: =COUNTIF(Promises!$C$2:$C$1047,"Haggai *") -> 6
A37: Zechariah | B37: =COUNTIF(Promises!$C$2:$C$1047,"Zechariah *") -> 15
A38: Malachi | B38: =COUNTIF(Promises!$C$2:$C$1047,"Malachi *") -> 8
A39: Matthew | B39: =COUNTIF(Promises!$C$2:$C$1047,"Matthew *") -> 39
A40: Mark | B40: =COUNTIF(Promises!$C$2:$C$1047,"Mark *") -> 9
...

Sheet Totals by Category
A1: Category | B1: Count
A2: Provision | B2: 89
A3: Presence | B3: 88
A4: Restoration | B4: 82
A5: Blessing | B5: 73
A6: Messiah | B6: 69
A7: Faithfulness | B7: 67
A8: Kingdom | B8: 67
A9: Mercy | B9: 64
A10: Covenant | B10: 59
A11: Protection | B11: 56
A12: Deliverance | B12: 53
A13: Salvation | B13: 52
... A107: Unity | B107: 1

Sheet Category Index (A-Z)
A1: Category | B1: Entry Numbers
A2: Abundance | B2: 860
A3: Acceptance | B3: 669, 670, 850
A4: Access | B4: 557, 570, 1045
A5: Acknowledgment | B5: 796, 833, 1026
A6: Adoption | B6: 714, 716, 784, 829, 842, 904, 931, 936, 1040
A7: Advocacy | B7: 1010
A8: Atonement | B8: 205, 541, 542, 665, 852, 1010
A9: Authority | B9: 831, 1025
A10: Blessing | B10: 16, 17, 18, 19, 21, 43, 52, 57, 61, 69, 101, 102, 106, 123, 131, 151, 152, 153, 154, 156, 157, 174, 175, 176, 177, 181, 182, 186, 188, 193, 194, 200, 214, 216, 233, 244, 255, 272, 292, 295, 297, 310, 322, 330, 353, 364, 369, 388, 392, 402, 408, 429, 436, 439, 458, 556, 565, 584, 597, 601, 639, 644, 679, 752, 761, 773, 885, 934, 935, 942, 959, 974, 1043
A11: Care | B11: 465, 656, 682, 795, 1002
A12: Church | B12: 802
... A107: Worship | B107: 467, 520, 669, 744, 769

Sheet Recipient Index
A1: Recipient | B1: Count | C1: Entry Numbers
A2: Israel | B2: 258 | C2: 74, 76, 81, 82, 83, 86, 87, 88, 89, 90, 91, 92, 93, 94, 95, 96, 97, 98, 99, 100, 101, 102, 103, 104, 105, 106, 107, 108, 109, 110, 111, 112, 114, 115, 116, 117, 118, 119, 120, 121, 122, 123, 124, 125, 126, 127, 128, 129, 130, 131, 132, 133, 135, 137, 138, 140, 141, 142, 143, 146, 147, 148, 149, 150, 151, 152, 153, 154, 155, 156, 157, 158, 159, 160, 161, 163, 164, 165, 166, 167, 168, 169, 170, 171, 172, 173, 174, 175, 176, 177, 178, 179, 180, 181, 182, 183, 184, 185, 186, 187, 188, 189, 190, 191, 192, 193, 194, 195, 196, 197, 198, 199, 200, 201, 202, 204, 205, 208, 209, 210, 211, 222, 223, 224, 225, 234, 238, 245, 258, 273, 282, 285, 288, 355, 356, 392, 394, 403, 448, 449, 450, 451, 453, 455, 458, 466, 476, 485, 497, 498, 499, 506, 508, 509, 510, 511, 512, 513, 515, 518, 521, 522, 523, 544, 545, 546, 547, 566, 575, 580, 590, 593, 596, 597, 600, 605, 606, 607, 613, 614, 615, 616, 619, 621, 622, 624, 626, 628, 631, 632, 633, 635, 637, 638, 639, 643, 647, 655, 657, 663, 666, 668, 669, 670, 671, 676, 677, 678, 679, 680, 681, 682, 684, 685, 686, 687, 688, 689, 690, 691, 692, 693, 694, 695, 696, 697, 698, 699, 700, 701, 702, 714, 715, 716, 717, 718, 719, 722, 723, 726, 727, 728, 729, 735, 747, 750, 751, 758, 760, 761, 770, 772, 773, 776, 825, 891, 914, 915
A3: Believers | B3: 85 | C3: 290, 303, 318, 330, 331, 347, 354, 410, 411, 426, 468, 497, 509, 856, 867, 868, 870, 875, 876, 883, 884, 900, 901, 903, 904, 905, 906, 909, 910, 916, 917, 920, 922, 923, 924, 925, 926, 927, 928, 930, 933, 937, 938, 939, 940, 942, 944, 946, 948, 949, 950, 951, 953, 954, 955, 957, 960, 961, 962, 963, 965, 967, 968, 969, 970, 972, 973, 975, 981, 982, 983, 986, 987, 988, 992, 993, 996, 997, 1004, 1008, 1010, 1012, 1016, 1017, 1018
A4: Disciples | B4: 37 | C4: 788, 789, 790, 791, 793, 794, 795, 797, 804, 805, 806, 807, 808, 815, 818, 820, 821, 822, 829, 831, 834, 836, 837, 838, 841, 867, 869, 870, 871, 874, 875, 878, 879, 880, 881, 882, 883
A5: His people | B5: 31 | C5: 313, 314, 315, 341, 342, 343, 370, 376, 377, 396, 397, 398, 463, 478, 481, 483, 493, 507, 521, 532, 534, 547, 555, 576, 585, 588, 627, 641, 658, 746, 763
A6: Zion | B6: 27 | C6: 374, 405, 406, 468, 472, 528, 529, 530, 531, 549, 568, 569, 570, 571, 572, 577, 578, 579, 617, 731, 732, 745, 746, 755, 757, 759, 762
A7: Judah | B7: 25 | C7: 75, 224, 270, 284, 287, 441, 442, 456, 470, 474, 581, 605, 606, 613, 631, 632, 640, 643, 645, 647, 648, 657, 754, 761, 764
A8: Jacob | B8: 20 | C8: 62, 63, 65, 66, 67, 68, 69, 70, 71, 72, 73, 499, 581, 615, 618, 625, 655, 699, 731, 738
A9: Jerusalem | B9: 20 | C9: 268, 475, 488, 490, 516, 535, 536, 583, 587, 595, 642, 644, 645, 648, 664, 665, 755, 756, 765, 766
A10: The righteous | B10: 20 | C10: 289, 292, 293, 297, 324, 325, 327, 334, 335, 336, 339, 345, 369, 432, 433, 435, 477, 480, 812, 1000
A11: All nations | B11: 19 | C11: 21, 55, 60, 64, 75, 306, 353, 443, 444, 448, 449, 519, 522, 524, 666, 706, 730, 734, 809
A12: David | B12: 18 | C12: 241, 242, 243, 244, 246, 247, 248, 251, 252, 272, 274, 275, 278, 318, 361, 362, 404, 407
A13: Abraham | B13: 14 | C13: 36, 37, 40, 42, 44, 45, 46, 47, 48, 49, 50, 52, 53, 974
... A318: weeping | B318: 1 | C318: 400

Sheet Read Me — Methodology
A1: THE COMPLETE INDEX OF GOD'S PROMISES IN SCRIPTURE — Combined Edition (Volumes 1 + 2)
A3: Total entries: 1046. Volume 1 laid the canonical spine (whole-promise granularity, all 66 books). Volume 2 added four expansion sweeps at clause-level granularity: Psalms exhaustive, Isaiah 40–66 clause-split, Deuteronomy 28 blessing-by-blessing, and the Jeremiah/Ezekiel restoration oracles. The 'Vol' column marks each entry's origin.
A4: Deuteronomy 28 note: Volume 1's block entries (28:3-6, 28:8, 28:11-12, 28:13) were superseded by their clause-split children per the counting rules — no double counting.
A5: Verification: every reference machine-checked against the full KJV text (public domain) for chapter:verse existence; content spot-checked for fidelity. Conditional = attached to stated human response. Unconditional = grounded solely in God's character, oath, or covenant.
A6: Books containing no direct divine promise: Esther, Song of Solomon, Philemon, 3 John.
A8: Dark red = Cross-landing entries (Messiah, atonement, substitution, resurrection, new covenant, salvation, justification). All the promises of God find their Yes in Christ Jesus — 2 Corinthians 1:20.
